<?xml version="1.0" encoding="UTF-8"?>

<robot xmlns:xacro="http://www.ros.org/wiki/xacro" name="panda">


<xacro:include filename = "$(find panda_bot_description)/urdf/panda_ros2_control.xacro"/>
<xacro:include filename = "$(find panda_bot_description)/urdf/panda_gazebo.xacro"/>

 <!-- Transmission macro -->
 <xacro:macro name="default_transmission" params="joint">
    <transmission name="${joint}_transmission">
        <type>transmission_interface/SimpleTransmission</type>
        <joint name="${joint}" role = "panda_joint1">
            <mechanicalReduction>1.0</mechanicalReduction>
        </joint>
        <actuator name="${joint}_motor" role = "actuator_1"/>
    </transmission>
</xacro:macro>


<!-- Links -->
<!-- World link-->
<link name="world"/>
<!-- Panda robot links -->

<!-- panda_link0 -->
<link name="panda_link0">
    <visual>
      <geometry>
        <mesh filename="package://panda_bot_description/meshes/visual/link0.dae"/>
      </geometry>
      <material name="panda_brown"/>
    </visual>
    <collision>
      <geometry>
        <mesh filename="package://panda_bot_description/meshes/collision/link0.obj"/>
      </geometry>
      <material name="panda_brown"/>
    </collision>
    <inertial>
      <mass value="0.629769"/>
      <inertia ixx="0.00315" iyy="0.00388" izz="0.004285" ixy="8.2904E-07" ixz="0.00015" iyz="8.2299E-06"/>
    </inertial>
  </link>
  
  <!-- panda_link1 -->
  <link name="panda_link1">
    <visual>
      <geometry>
        <mesh filename="package://panda_bot_description/meshes/visual/link1.dae"/>
      </geometry>
      <material name="panda_brown"/>
    </visual>
    <collision>
      <geometry>
        <mesh filename="package://panda_bot_description/meshes/collision/link1.obj"/>
      </geometry>
      <material name="panda_brown"/>
    </collision>
    <inertial>
      <mass value="4.970684"/>
      <inertia ixx="0.70337" iyy="0.70661" izz="0.0091170" ixy="-0.00013900" ixz="0.0067720" iyz="0.019169"/>
    </inertial>
  </link>
  
  <!-- panda_link2 -->
  <link name="panda_link2">
    <visual>
      <geometry>
        <mesh filename="package://panda_bot_description/meshes/visual/link2.dae"/>
      </geometry>
      <material name="panda_brown"/>
    </visual>
    <collision>
      <geometry>
        <mesh filename="package://panda_bot_description/meshes/collision/link2.obj"/>
      </geometry>
      <material name="panda_brown"/>
    </collision>
    <inertial>
      <mass value="0.646926"/>
      <inertia ixx="0.0079620" iyy="2.8110e-02" izz="2.5995e-02" ixy="-3.9250e-3" ixz="1.0254e-02" iyz="7.0400e-04"/>
    </inertial>
  </link>
  
  <!-- panda_link3 -->
  <link name="panda_link3">
    <visual>
      <geometry>
        <mesh filename="package://panda_bot_description/meshes/visual/link3.dae"/>
      </geometry>
      <material name="panda_brown"/>
    </visual>
    <collision>
      <geometry>
        <mesh filename="package://panda_bot_description/meshes/collision/link3.obj"/>
      </geometry>
      <material name="panda_brown"/>
    </collision>
    <inertial>
      <mass value="3.228604"/>
      <inertia ixx="3.7242e-02" iyy="3.6155e-02" izz="1.0830e-02" ixy="-4.7610e-03" ixz="-1.1396e-02" iyz="-1.2805e-02"/>
    </inertial>
  </link>
  
  <!-- panda_link4 -->
  <link name="panda_link4">
    <visual>
      <geometry>
        <mesh filename="package://panda_bot_description/meshes/visual/link4.dae"/>
      </geometry>
      <material name="panda_brown"/>
    </visual>
    <collision>
      <geometry>
        <mesh filename="package://panda_bot_description/meshes/collision/link4.obj"/>
      </geometry>
      <material name="panda_brown"/>
    </collision>
    <inertial>
      <mass value="3.587895"/>
      <inertia ixx="2.5853e-02" iyy="1.9552e-02" izz="2.8323e-02" ixy="7.7960e-03" ixz="-1.3320e-03" iyz="8.6410e-03"/>
    </inertial>
  </link>
  
  <!-- panda_link5 -->
  <link name="panda_link5">
    <visual>
      <geometry>
        <mesh filename="package://panda_bot_description/meshes/visual/link5.dae"/>
      </geometry>
      <material name="panda_brown"/>
    </visual>
    <collision>
      <geometry>
        <mesh filename="package://panda_bot_description/meshes/collision/link5.obj"/>
      </geometry>
      <material name="panda_brown"/>
    </collision>
    <inertial>
      <mass value="1.225946"/>
      <inertia ixx="3.5549e-02" iyy="2.9474e-02" izz="8.6270e-03" ixy="-2.1170e-03" ixz="-4.0370e-03" iyz="2.2900e-04"/>
    </inertial>
  </link>
  
  <!-- panda_link6 -->
  <link name="panda_link6">
    <visual>
      <geometry>
        <mesh filename="package://panda_bot_description/meshes/visual/link6.dae"/>
      </geometry>
      <material name="panda_brown"/>
    </visual>
    <collision>
      <geometry>
        <mesh filename="package://panda_bot_description/meshes/collision/link6.obj"/>
      </geometry>
      <material name="panda_brown"/>
    </collision>
    <inertial>
      <mass value="1.666555"/>
      <inertia ixx="1.9640e-03" iyy="4.3540e-03" izz="5.4330e-03" ixy="1.0900e-04" ixz="-1.1580e-03" iyz="3.4100e-04"/>
    </inertial>
  </link>
  
  <!-- panda_link7 -->
  <link name="panda_link7">
    <visual>
      <geometry>
        <mesh filename="package://panda_bot_description/meshes/visual/link7.dae"/>
      </geometry>
      <material name="panda_brown"/>
    </visual>
    <collision>
      <geometry>
        <mesh filename="package://panda_bot_description/meshes/collision/link7.obj"/>
      </geometry>
      <material name="panda_brown"/>
    </collision>
    <inertial>
      <mass value="7.35522e-01"/>
      <inertia ixx="1.2516e-02" iyy="1.0027e-02" izz="4.8150e-03" ixy="-4.2800e-04" ixz="-1.1960e-03" iyz="-7.4100e-04"/>
    </inertial>
  </link>
  
  <link name="panda_link8"/>
  
  <link name="panda_hand">
    <visual>
      <geometry>
        <mesh filename="package://panda_bot_description/meshes/visual/hand.dae"/>
      </geometry>
      <material name="panda_brown"/>
    </visual>
    <collision>
      <geometry>
        <mesh filename="package://panda_bot_description/meshes/collision/hand.obj"/>
      </geometry>
      <material name="panda_brown"/>
    </collision>
    <inertial>
      <mass value="0.73"/>
      <inertia ixx="0.001" iyy="0.0025" izz="0.0017" ixy="0" ixz="0" iyz="0"/>
    </inertial>
  </link>
  
  <!-- panda_leftfinger -->
  <link name="panda_leftfinger">
    <visual>
      <geometry>
        <mesh filename="package://panda_bot_description/meshes/visual/finger.dae"/>
      </geometry>
      <material name="panda_brown"/>
    </visual>
    <collision>
      <geometry>
        <mesh filename="package://panda_bot_description/meshes/collision/finger.obj"/>
      </geometry>
      <material name="panda_brown"/>
    </collision>
    <inertial>
      <mass value="0.015"/>
      <inertia ixx="2.3749999999999997e-06" iyy="2.3749999999999997e-06" izz="7.5e-07" ixy="0" ixz="0" iyz="0"/>
    </inertial>
  </link>
  
  <!-- panda_rightfinger -->
  <link name="panda_rightfinger">
    <visual>
        <origin rpy="0.0 0.0 3.14159265359"/>
      <geometry>
        <mesh filename="package://panda_bot_description/meshes/visual/finger.dae"/>
      </geometry>
      <material name="panda_brown"/>
    </visual>
    <collision>
      <geometry>
        <mesh filename="package://panda_bot_description/meshes/collision/finger.obj"/>
      </geometry>
      <material name="panda_brown"/>
    </collision>
    <inertial>
      <mass value="0.015"/>
      <inertia ixx="2.3749999999999997e-06" iyy="2.3749999999999997e-06" izz="7.5e-07" ixy="0" ixz="0" iyz="0"/>
    </inertial>
  </link>
  

<!-- Joints -->
<joint name="virtual_joint" type="fixed">
    <origin xyz="0.0 0.0 0.0" rpy="0.0 0.0 0.0"/>
    <parent link="world"/>
    <child link="panda_link0"/>
</joint>

<joint name="panda_joint1" type="revolute">
    <safety_controller k_position="100.0" k_velocity="40.0" soft_lower_limit="-2.8973" soft_upper_limit="2.8973"/>
    <origin rpy="0 0 0" xyz="0 0 0.333"/>
    <parent link="panda_link0"/>
    <child link="panda_link1"/>
    <axis xyz="0 0 1"/>
    <limit effort="87" lower="-2.9671" upper="2.9671" velocity="2.1750"/>
  </joint>

  <joint name="panda_joint2" type="revolute">
    <safety_controller k_position="100.0" k_velocity="40.0" soft_lower_limit="-1.7628" soft_upper_limit="1.7628"/>
    <origin rpy="-1.57079632679 0 0" xyz="0 0 0"/>
    <parent link="panda_link1"/>
    <child link="panda_link2"/>
    <axis xyz="0 0 1"/>
    <limit effort="87" lower="-1.8326" upper="1.8326" velocity="2.1750"/>
  </joint>

  <joint name="panda_joint3" type="revolute">
    <safety_controller k_position="100.0" k_velocity="40.0" soft_lower_limit="-2.8973" soft_upper_limit="2.8973"/>
    <origin rpy="1.57079632679 0 0" xyz="0 -0.316 0"/>
    <parent link="panda_link2"/>
    <child link="panda_link3"/>
    <axis xyz="0 0 1"/>
    <limit effort="87" lower="-2.9671" upper="2.9671" velocity="2.1750"/>
  </joint>

  <joint name="panda_joint4" type="revolute">
    <safety_controller k_position="100.0" k_velocity="40.0" soft_lower_limit="-3.0718" soft_upper_limit="-0.0698"/>
    <origin rpy="1.57079632679 0 0" xyz="0.0825 0 0"/>
    <parent link="panda_link3"/>
    <child link="panda_link4"/>
    <axis xyz="0 0 1"/>
    <limit effort="87" lower="-3.1416" upper="0.0" velocity="2.1750"/>
  </joint>

  <joint name="panda_joint5" type="revolute">
    <safety_controller k_position="100.0" k_velocity="40.0" soft_lower_limit="-2.8973" soft_upper_limit="2.8973"/>
    <origin rpy="-1.57079632679 0 0" xyz="-0.0825 0.384 0"/>
    <parent link="panda_link4"/>
    <child link="panda_link5"/>
    <axis xyz="0 0 1"/>
    <limit effort="12" lower="-2.9671" upper="2.9671" velocity="2.6100"/>
  </joint>

  <joint name="panda_joint6" type="revolute">
    <safety_controller k_position="100.0" k_velocity="40.0" soft_lower_limit="-0.0175" soft_upper_limit="3.7525"/>
    <origin rpy="1.57079632679 0 0" xyz="0 0 0"/>
    <parent link="panda_link5"/>
    <child link="panda_link6"/>
    <axis xyz="0 0 1"/>
    <limit effort="12" lower="-0.0873" upper="3.8223" velocity="2.6100"/>   
  </joint>

  <joint name="panda_joint7" type="revolute">
    <safety_controller k_position="100.0" k_velocity="40.0" soft_lower_limit="-2.8973" soft_upper_limit="2.8973"/>
    <origin rpy="1.57079632679 0 0" xyz="0.088 0 0"/>
    <parent link="panda_link6"/>
    <child link="panda_link7"/>
    <axis xyz="0 0 1"/>
    <limit effort="12" lower="-2.9671" upper="2.9671" velocity="2.6100"/>
  </joint>

  <joint name="panda_joint8" type="fixed">
    <origin rpy="0 0 0" xyz="0 0 0.107"/>
    <parent link="panda_link7"/>
    <child link="panda_link8"/>
    <axis xyz="0 0 0"/>
  </joint>

  <joint name="panda_hand_joint" type="fixed">
    <parent link="panda_link8"/>
    <child link="panda_hand"/>
    <origin rpy="0 0 -0.785398163397" xyz="0 0 0"/>
  </joint>

  <joint name="panda_finger_joint1" type="prismatic">
    <parent link="panda_hand"/>
    <child link="panda_leftfinger"/>
    <origin rpy="0 0 0" xyz="0 0 0.0584"/>
    <axis xyz="0 1 0"/>
    <limit effort="20" lower="0.0" upper="0.04" velocity="0.2"/>
  </joint>
  <joint name="panda_finger_joint2" type="prismatic">
    <parent link="panda_hand"/>
    <child link="panda_rightfinger"/>
    <origin rpy="0 0 0" xyz="0 0 0.0584"/>
    <axis xyz="0 -1 0"/>
    <limit effort="20" lower="0.0" upper="0.04" velocity="0.2"/>
    <mimic joint="panda_finger_joint1"/>
  </joint>
  
  <material name="panda_brown">
    <color rgba="0.556 0.22 0.043 1."/>
  </material>

  <!-- Transmission -->
    <xacro:default_transmission joint="panda_joint1"/>
    <xacro:default_transmission joint="panda_joint2"/>
    <xacro:default_transmission joint="panda_joint3"/>
    <xacro:default_transmission joint="panda_joint4"/>
    <xacro:default_transmission joint="panda_joint5"/>
    <xacro:default_transmission joint="panda_joint6"/>
    <xacro:default_transmission joint="panda_joint7"/>
    <xacro:default_transmission joint="panda_finger_joint1"/>

</robot>